Workbook

Sheet Resultats
B1: INSTANCES FOURNIES PAR GOOGLE | Z1: Classement hashcode
P2: =COUNTA(C3:O3) -> 13 | Z2: Classement | AA2: Score
A3: instance \ score groupe | B3: VBS | C3: A | D3: B | E3: C | F3: D | G3: E | H3: F | I3: G | J3: H | K3: I | L3: J | M3: K | N3: L | O3: P | P3: Lowest Score | Q3: Borne Inf | Z3: 1 | AA3: 2651999
A4: kittens | B4: =max(C4:N4) -> 1025079 | C4: 1022556 | D4: 507470 | E4: 1021696 | F4: 1022115 | G4: 967433 | H4: 964093 | I4: 858883 | L4: 193260 | M4: 1025079 | P4: =MINIFS($C4:$O4,$C4:$O4,">0") -> 193260 | Z4: 2 | AA4: 2650005
A5: me_at_the_zoo | B5: =max(C5:N5) -> 516557 | C5: 507906 | D5: 301747 | E5: 512115 | F5: 507906 | G5: 505619 | H5: 497300 | I5: 491182 | L5: 464429 | M5: 516557 | P5: =MINIFS($C5:$O5,$C5:$O5,">0") -> 301747 | Z5: 3 | AA5: 2649544
A6: trending_today | B6: =max(C6:N6) -> 500000 | C6: 499966 | D6: 327080 | E6: 499966 | F6: 499966 | G6: 499979 | H6: 499966 | I6: 499991 | L6: 499797 | M6: 500000 | P6: =MINIFS($C6:$O6,$C6:$O6,">0") -> 327080 | Z6: 4 | AA6: 2646990
A7: videos_worth_spreading | B7: =max(C7:N7) -> 614545 | C7: 611597 | D7: 24748 | E7: 610596 | F7: 609385 | G7: 605129 | H7: 603656 | I7: 560579 | L7: 537419 | M7: 614545 | P7: =MINIFS($C7:$O7,$C7:$O7,">0") -> 24748 | Z7: 5 | AA7: 2646341
Z8: 6 | AA8: 2645237
A9: TOTAL | B9: {=SUM(IFERROR(B4:B7*1,VALUE(SUBSTITUTE(B4:B7," ",""))))} -> 2656181 | C9: {=SUM(IFERROR(C4:C7*1,VALUE(SUBSTITUTE(C4:C7," ",""))))} -> 2642025 | D9: {=SUM(IFERROR(D4:D7*1,VALUE(SUBSTITUTE(D4:D7," ",""))))} -> 1161045 | E9: {=SUM(IFERROR(E4:E7*1,VALUE(SUBSTITUTE(E4:E7," ",""))))} -> 2644373 | F9: {=SUM(IFERROR(F4:F7*1,VALUE(SUBSTITUTE(F4:F7," ",""))))} -> 2639372 | G9: {=SUM(IFERROR(G4:G7*1,VALUE(SUBSTITUTE(G4:G7," ",""))))} -> 2578160 | H9: {=SUM(IFERROR(H4:H7*1,VALUE(SUBSTITUTE(H4:H7," ",""))))} -> 2565015 | I9: {=SUM(IFERROR(I5:I7*1,VALUE(SUBSTITUTE(I5:I7," ",""))))} -> 1551752 | J9: {=SUM(IFERROR(J4:J7*1,VALUE(SUBSTITUTE(J4:J7," ",""))))} -> 0 | K9: {=SUM(IFERROR(K4:K7*1,VALUE(SUBSTITUTE(K4:K7," ",""))))} -> 0 | L9: {=SUM(IFERROR(L4:L7*1,VALUE(SUBSTITUTE(L4:L7," ",""))))} -> 1694905 | M9: {=SUM(IFERROR(M4:M7*1,VALUE(SUBSTITUTE(M4:M7," ",""))))} -> 2656181 | N9: {=SUM(IFERROR(N4:N7*1,VALUE(SUBSTITUTE(N4:N7," ",""))))} -> 0 | O9: {=SUM(IFERROR(O4:O7*1,VALUE(SUBSTITUTE(O4:O7," ",""))))} -> 0 | Z9: 7 | AA9: 2644948
Z10: 8 | AA10: 2644019
A11: Classement Hashcode | B11: =IF(B9=0, "", COUNTIF($AA$3:$AA$2817, ">"&B9) + 1) -> 3 | C11: =IF(C9=0, "", COUNTIF($AA$3:$AA$2817, ">"&C9) + 1) -> 12 | D11: =IF(D9=0, "", COUNTIF($AA$3:$AA$2817, ">"&D9) + 1) -> 1573 | E11: =IF(E9=0, "", COUNTIF($AA$3:$AA$2817, ">"&E9) + 1) -> 10 | F11: =IF(F9=0, "", COUNTIF($AA$3:$AA$2817, ">"&F9) + 1) -> 18 | G11: =IF(G9=0, "", COUNTIF($AA$3:$AA$2817, ">"&G9) + 1) -> 56 | H11: =IF(H9=0, "", COUNTIF($AA$3:$AA$2817, ">"&H9) + 1) -> 66 | I11: =IF(I9=0, "", COUNTIF($AA$3:$AA$2817, ">"&I9) + 1) -> 1272 | ... N11: =IF(N9=0, "", COUNTIF($AA$3:$AA$2817, ">"&N9) + 1) | Z11: 9 | AA11: 2642844
A12: Classement Local | C12: =IF(C9=0, $P$2, RANK(C9,$C$9:$N$9,0)) -> 3 | D12: =IF(D9=0, $P$2, RANK(D9,$C$9:$N$9,0)) -> 9 | E12: =IF(E9=0, $P$2, RANK(E9,$C$9:$N$9,0)) -> 2 | F12: =IF(F9=0, $P$2, RANK(F9,$C$9:$N$9,0)) -> 4 | G12: =IF(G9=0, $P$2, RANK(G9,$C$9:$N$9,0)) -> 5 | H12: =IF(H9=0, $P$2, RANK(H9,$C$9:$N$9,0)) -> 6 | I12: =IF(I9=0, $P$2, RANK(I9,$C$9:$N$9,0)) -> 8 | J12: =IF(J9=0, $P$2, RANK(J9,$C$9:$N$9,0)) -> 13 | ... O12: =IF(O9=0, $P$2, RANK(O9,$C$9:$N$9,0)) -> 13 | Z12: 10 | AA12: 2641955
Z13: 11 | AA13: 2641125
Z14: 12 | AA14: 2641021
B15: INSTANCES DE LA PROMO | Z15: 13 | AA15: 2640554
Z16: 14 | AA16: 2640476
A17: TOTAL | C17: {=IFERROR(SUM(IFERROR(C21:C67*1,VALUE(SUBSTITUTE(C21:C67," ","")))),"")} -> 23888988 | D17: {=IFERROR(SUM(IFERROR(D21:D67*1,VALUE(SUBSTITUTE(D21:D67," ","")))),"")} -> 2692842 | E17: {=IFERROR(SUM(IFERROR(E21:E67*1,VALUE(SUBSTITUTE(E21:E67," ","")))),"")} -> 25636316 | F17: {=IFERROR(SUM(IFERROR(F21:F67*1,VALUE(SUBSTITUTE(F21:F67," ","")))),"")} -> 5841451 | G17: {=IFERROR(SUM(IFERROR(G21:G67*1,VALUE(SUBSTITUTE(G21:G67," ","")))),"")} -> 19750179 | H17: {=IFERROR(SUM(IFERROR(H21:H67*1,VALUE(SUBSTITUTE(H21:H67," ","")))),"")} -> 23576321 | I17: {=IFERROR(SUM(IFERROR(I21:I67*1,VALUE(SUBSTITUTE(I21:I67," ","")))),"")} -> 25480481 | J17: {=IFERROR(SUM(IFERROR(J21:J67*1,VALUE(SUBSTITUTE(J21:J67," ","")))),"")} -> 0 | ... O17: {=IFERROR(SUM(IFERROR(O21:O67*1,VALUE(SUBSTITUTE(O21:O67," ","")))),"")} -> 0 | Z17: 15 | AA17: 2640301
A18: Classement Local | C18: =IF(C17=0, $P$2, RANK(C17,$C$17:$N$17,0)) -> 3 | D18: =IF(D17=0, $P$2, RANK(D17,$C$17:$N$17,0)) -> 9 | E18: =IF(E17=0, $P$2, RANK(E17,$C$17:$N$17,0)) -> 1 | F18: =IF(F17=0, $P$2, RANK(F17,$C$17:$N$17,0)) -> 7 | G18: =IF(G17=0, $P$2, RANK(G17,$C$17:$N$17,0)) -> 5 | H18: =IF(H17=0, $P$2, RANK(H17,$C$17:$N$17,0)) -> 4 | I18: =IF(I17=0, $P$2, RANK(I17,$C$17:$N$17,0)) -> 2 | J18: =IF(J17=0, $P$2, RANK(J17,$C$17:$N$17,0)) -> 13 | ... O18: =IF(O17=0, $P$2, RANK(O17,$C$17:$N$17,0)) -> 13 | Z18: 16 | AA18: 2639308
Z19: 17 | AA19: 2638862
A20: instance \ score groupe | B20: VBS | C20: A | D20: B | E20: C | F20: D | G20: E | H20: F | I20: G | J20: H | K20: I | L20: J | M20: K | N20: L | O20: P | P20: Lowest Score | Q20: Borne Inf | Z20: 18 | AA20: 2638613
A21: custom_dejavu42 | B21: =max(C21:N21) -> 64697 | C21: 64697 | D21: 6679 | E21: 64548 | F21: 64428 | G21: 62583 | H21: 62279 | I21: 59794 | L21: 50225 | M21: 64385 | P21: =MINIFS($C21:$O21,$C21:$O21,">0") -> 6679 | Z21: 19 | AA21: 2638601
A22: custom_universallambda42 | B22: =max(C22:N22) -> 1342673 | C22: 1342673 | D22: 239241 | E22: 1341814 | F22: 1339620 | G22: 1342549 | H22: 1341745 | I22: 1338984 | L22: 1198668 | M22: 1339375 | P22: =MINIFS($C22:$O22,$C22:$O22,">0") -> 239241 | Z22: 20 | AA22: 2638033
A23: custom_universallambda42_asymmetric | B23: =max(C23:N23) -> 975514 | C23: 975514 | D23: 459625 | E23: 975017 | F23: 974865 | G23: 971833 | H23: 971786 | I23: 971867 | L23: 141391 | M23: 974865 | P23: =MINIFS($C23:$O23,$C23:$O23,">0") -> 141391 | Z23: 21 | AA23: 2637842
A24: instance1 (corrigée) | B24: =max(C24:N24) -> 1498093 | C24: 1498093 | D24: 1364340 | E24: 1496436 | F24: 1496448 | G24: 1496448 | H24: 1417781 | I24: 1383174 | L24: 954936 | M24: 1496236 | P24: =MINIFS($C24:$O24,$C24:$O24,">0") -> 954936 | Z24: 22 | AA24: 2637829
A25: instance2 (corrigée) | B25: =max(C25:N25) -> 1971053 | C25: 1971053 | D25: 622957 | E25: 1965727 | F25: 1966090 | G25: 1919527 | H25: 1915567 | I25: 1884259 | L25: 1368368 | M25: 1965363 | P25: =MINIFS($C25:$O25,$C25:$O25,">0") -> 622957 | Z25: 23 | AA25: 2637814
A26: 4990_246_84901_50.in | B26: =max(C26:N26) -> 1798985 | C26: 1798880 | E26: 1798985 | G26: 1733652 | H26: 1728816 | I26: 1711923 | L26: 839358 | P26: =MINIFS($C26:$O26,$C26:$O26,">0") -> 839358 | Z26: 24 | AA26: 2637310
A27: 6970_311_100000_69.in | B27: =max(C27:N27) -> 1836469 | C27: 1836310 | E27: 1836469 | G27: 1805632 | H27: 1801898 | I27: 1774189 | L27: 1252441 | P27: =MINIFS($C27:$O27,$C27:$O27,">0") -> 1252441 | Z27: 25 | AA27: 2636013
A28: 10000_500_100000_100.in | B28: =max(C28:N28) -> 2019441 | C28: 2019395 | E28: 2019433 | G28: 2019441 | H28: 2017043 | I28: 2006485 | L28: 1120292 | P28: =MINIFS($C28:$O28,$C28:$O28,">0") -> 1120292 | Z28: 26 | AA28: 2632701
A29: 3860_246_84901_66.in | B29: =max(C29:N29) -> 1977713 | C29: 1976501 | E29: 1976566 | G29: 1977713 | H29: 1976032 | I29: 1969132 | L29: 1230495 | P29: =MINIFS($C29:$O29,$C29:$O29,">0") -> 1230495 | Z29: 27 | AA29: 2632267
A30: regional_instance.in | B30: =max(C30:N30) -> 2370771 | C30: 2362511 | E30: 2370771 | G30: 2366036 | H30: 2346109 | I30: 2307011 | L30: 2298160 | P30: =MINIFS($C30:$O30,$C30:$O30,">0") -> 2298160 | Z30: 28 | AA30: 2629225
A31: zipF_instance.in | B31: =max(C31:N31) -> 1919449 | C31: 1903658 | E31: 1919449 | G31: 1906354 | H31: 1889273 | I31: 1879209 | L31: 1886973 | P31: =MINIFS($C31:$O31,$C31:$O31,">0") -> 1879209 | Z31: 29 | AA31: 2628586
A32: big.in | B32: =max(C32:N32) -> 271267 | C32: 249794 | E32: 271267 | G32: 249794 | H32: 249794 | I32: 271267 | L32: 249794 | P32: =MINIFS($C32:$O32,$C32:$O32,">0") -> 249794 | Z32: 30 | AA32: 2628109
A33: supra.in | B33: =max(C33:N33) -> 411743 | C33: 369631 | E33: 411743 | G33: 369631 | H33: 369631 | I33: 411743 | L33: 369631 | P33: =MINIFS($C33:$O33,$C33:$O33,">0") -> 369631 | Z33: 31 | AA33: 2627501
A34: INSATANC2D.in | B34: =max(C34:N34) -> 249794 | C34: 131569 | E34: 131804 | G34: 249794 | H34: 126093 | I34: 121406 | P34: =MINIFS($C34:$O34,$C34:$O34,">0") -> 121406 | Z34: 32 | AA34: 2625970
A35: INSTANCED.in | B35: =max(C35:N35) -> 1283215 | C35: 1272204 | E35: 1281461 | G35: 1279192 | H35: 1271986 | I35: 1283215 | P35: =MINIFS($C35:$O35,$C35:$O35,">0") -> 1271986 | Z35: 33 | AA35: 2625294
A36: 2_2_2_1.in | B36: =max(C36:N36) -> 951327 | C36: 47672 | E36: 951327 | H36: 47672 | I36: 951327 | P36: =MINIFS($C36:$O36,$C36:$O36,">0") -> 47672 | Z36: 34 | AA36: 2624840
A37: 4_2_4_2.in | B37: =max(C37:N37) -> 671392 | C37: 344442 | E37: 655321 | H37: 344442 | I37: 671392 | P37: =MINIFS($C37:$O37,$C37:$O37,">0") -> 344442 | Z37: 35 | AA37: 2620094
A38: 6_2_6_2.in | B38: =max(C38:N38) -> 832174 | C38: 499524 | E38: 499524 | H38: 499524 | I38: 832174 | P38: =MINIFS($C38:$O38,$C38:$O38,">0") -> 499524 | Z38: 36 | AA38: 2620067
A39: 8_2_8_2.in | B39: =max(C39:N39) -> 857014 | C39: 432762 | E39: 567228 | H39: 432762 | I39: 857014 | P39: =MINIFS($C39:$O39,$C39:$O39,">0") -> 432762 | Z39: 37 | AA39: 2618848
A40: 20_2_20_2.in | B40: =max(C40:N40) -> 524928 | C40: 475171 | E40: 524928 | H40: 475171 | I40: 524928 | P40: =MINIFS($C40:$O40,$C40:$O40,">0") -> 475171 | Z40: 38 | AA40: 2615393
...

Sheet Stats Instances
F1: Meilleur résultat | G1: Groupe | I1: Moyenne | J1: Min
A2: Instance : | B2: custom_universallambda42_asymmetric | D2: =IF(B2="kittens",4,IF(B2="me_at_the_zoo",5,IF(B2="trending_today",6,IF(B2="videos_worth_spreading",7,IF(B2="custom_dejavu42",21,IF(B2="custom_universallambda42",22,IF(B2="custom_universallambda42_asymmetric",23,IF(B2="instance1",24,IF(B2="instance2",25,""))))))))) -> 23 | F2: =MAX(B5:M5) -> 975514 | G2: {=INDEX(B4:M4,1,MATCH(MAX(B5:M5),B5:M5,0))} -> A | I2: =AVERAGE($B$5:$N$5) -> 824084.78 | J2: =MINIFS($B$5:$N$5,$B$5:$N$5,">0") -> 141391
A4: Groupes | B4: A | C4: B | D4: C | E4: D | F4: E | G4: F | H4: G | I4: H | J4: I | K4: J | L4: K | M4: L | N4: P
A5: Score | B5: {=INDIRECT("Resultats!C"&D2)} -> 975514 | C5: {=INDIRECT("Resultats!D"&D2)} -> 459625 | D5: {=INDIRECT("Resultats!E"&D2)} -> 975017 | E5: {=INDIRECT("Resultats!F"&D2)} -> 974865 | F5: {=INDIRECT("Resultats!G"&D2)} -> 971833 | G5: {=INDIRECT("Resultats!H"&D2)} -> 971786 | H5: {=INDIRECT("Resultats!I"&D2)} -> 971867 | I5: {=INDIRECT("Resultats!J"&D2)} | J5: {=INDIRECT("Resultats!K"&D2)} | K5: {=INDIRECT("Resultats!L"&D2)} -> 141391 | L5: {=INDIRECT("Resultats!M"&D2)} -> 974865 | M5: {=INDIRECT("Resultats!N"&D2)} | N5: {=INDIRECT("Resultats!O"&D2)}
A6: Rang | B6: =IF(B$5="","",RANK(B$5,$B$5:$M$5,0)) -> 1 | C6: =IF(C$5="","",RANK(C$5,$B$5:$M$5,0)) -> 8 | D6: =IF(D$5="","",RANK(D$5,$B$5:$M$5,0)) -> 2 | E6: =IF(E$5="","",RANK(E$5,$B$5:$M$5,0)) -> 3 | F6: =IF(F$5="","",RANK(F$5,$B$5:$M$5,0)) -> 6 | G6: =IF(G$5="","",RANK(G$5,$B$5:$M$5,0)) -> 7 | H6: =IF(H$5="","",RANK(H$5,$B$5:$M$5,0)) -> 5 | I6: =IF(I$5="","",RANK(I$5,$B$5:$M$5,0)) | ... L6: =IF(L$5="","",RANK(L$5,$B$5:$M$5,0)) -> 3
A7: Déviation | B7: =IF(B$5="","",B5-$F$2) -> 0 | C7: =IF(C$5="","",C5-$F$2) -> -515889 | D7: =IF(D$5="","",D5-$F$2) -> -497 | E7: =IF(E$5="","",E5-$F$2) -> -649 | F7: =IF(F$5="","",F5-$F$2) -> -3681 | G7: =IF(G$5="","",G5-$F$2) -> -3728 | H7: =IF(H$5="","",H5-$F$2) -> -3647 | I7: =IF(I$5="","",I5-$F$2) | ... N7: =IF(N$5="","",N5-$F$2)
A8: Ratio eu meilleur | B8: =IF(B$5="","",B$5/$F$2) -> 1 | C8: =IF(C$5="","",C$5/$F$2) -> 0.47116187 | D8: =IF(D$5="","",D$5/$F$2) -> 0.99949053 | E8: =IF(E$5="","",E$5/$F$2) -> 0.99933471 | F8: =IF(F$5="","",F$5/$F$2) -> 0.9962266 | G8: =IF(G$5="","",G$5/$F$2) -> 0.99617842 | H8: =IF(H$5="","",H$5/$F$2) -> 0.99626146 | I8: =IF(I$5="","",I$5/$F$2) | ... N8: =IF(N$5="","",N$5/$F$2)
A9: Z-score | B9: =IF(B$5="","",(B$5-$I$2)/STDEV($B$5:$N$5)) -> 0.49274036 | C9: =IF(C$5="","",(C$5-$I$2)/STDEV($B$5:$N$5)) -> -1.1859273 | D9: =IF(D$5="","",(D$5-$I$2)/STDEV($B$5:$N$5)) -> 0.49112316 | E9: =IF(E$5="","",(E$5-$I$2)/STDEV($B$5:$N$5)) -> 0.49062856 | F9: =IF(F$5="","",(F$5-$I$2)/STDEV($B$5:$N$5)) -> 0.48076264 | G9: =IF(G$5="","",(G$5-$I$2)/STDEV($B$5:$N$5)) -> 0.4806097 | H9: =IF(H$5="","",(H$5-$I$2)/STDEV($B$5:$N$5)) -> 0.48087327 | I9: =IF(I$5="","",(I$5-$I$2)/STDEV($B$5:$N$5)) | ... N9: =IF(N$5="","",(N$5-$I$2)/STDEV($B$5:$N$5))
A10: Ecart a la moyenne | B10: =IF(B$5="","",B$5/$I$2-1) -> 0.18375442 | C10: =IF(C$5="","",C$5/$I$2-1) -> -0.44226005 | D10: =IF(D$5="","",D$5/$I$2-1) -> 0.18315133 | E10: =IF(E$5="","",E$5/$I$2-1) -> 0.18296688 | F10: =IF(F$5="","",F$5/$I$2-1) -> 0.17928765 | G10: =IF(G$5="","",G$5/$I$2-1) -> 0.17923062 | H10: =IF(H$5="","",H$5/$I$2-1) -> 0.17932891 | I10: =IF(I$5="","",I$5/$I$2-1) | ... N10: =IF(N$5="","",N$5/$I$2-1)
A11: Ecart a la médiane | B11: =IF(B$5="","",B$5/MEDIAN($B$5:$N$5)) -> 1.0037526 | C11: =IF(C$5="","",C$5/MEDIAN($B$5:$N$5)) -> 0.47292994 | D11: =IF(D$5="","",D$5/MEDIAN($B$5:$N$5)) -> 1.0032412 | E11: =IF(E$5="","",E$5/MEDIAN($B$5:$N$5)) -> 1.0030848 | F11: =IF(F$5="","",F$5/MEDIAN($B$5:$N$5)) -> 0.99996502 | G11: =IF(G$5="","",G$5/MEDIAN($B$5:$N$5)) -> 0.99991666 | H11: =IF(H$5="","",H$5/MEDIAN($B$5:$N$5)) -> 1 | I11: =IF(I$5="","",I$5/MEDIAN($B$5:$N$5)) | ... N11: =IF(N$5="","",N$5/MEDIAN($B$5:$N$5))
A12: normalisation min-max | B12: =IF(B5="","",(B5-$J$2)/($F$2-$J$2)) -> 1 | C12: =IF(C5="","",(C5-$J$2)/($F$2-$J$2)) -> 0.38151927 | D12: =IF(D5="","",(D5-$J$2)/($F$2-$J$2)) -> 0.99940416 | E12: =IF(E5="","",(E5-$J$2)/($F$2-$J$2)) -> 0.99922194 | F12: =IF(F5="","",(F5-$J$2)/($F$2-$J$2)) -> 0.99558698 | G12: =IF(G5="","",(G5-$J$2)/($F$2-$J$2)) -> 0.99553064 | H12: =IF(H5="","",(H5-$J$2)/($F$2-$J$2)) -> 0.99562774 | I12: =IF(I5="","",(I5-$J$2)/($F$2-$J$2)) | ... N12: =IF(N5="","",(N5-$J$2)/($F$2-$J$2))

Sheet Classement
A1: Premiers tests de classements | P1: CLASSEMENT Google | S1: Classement ecarta la moyenne
P2: Groupe | Q2: Score | AF2: =COUNTA(T3:AF3) -> 13
A3: Classement à la Google | P3: {=(CHOOSECOLS(SORT(TRANSPOSE(CHOOSEROWS(B5:N7,1,3,2)),2,TRUE),1,3))} -> K | Q3: 2656181 | S3: Groupe | T3: A | U3: B | V3: C | W3: D | X3: E | Y3: F | Z3: G | AA3: H | AB3: I | AC3: J | AD3: K | AE3: L | AF3: P
N4: =COUNTA(B5:N5) -> 13 | P4: C | Q4: 2644373 | S4: kittens | T4: =IF(Resultats!C4="","",Resultats!C4/AVERAGE(Resultats!$C4:Resultats!$O4)) -> 1.2137027 | U4: =IF(Resultats!D4="","",Resultats!D4/AVERAGE(Resultats!$C4:Resultats!$O4)) -> 0.60233153 | V4: =IF(Resultats!E4="","",Resultats!E4/AVERAGE(Resultats!$C4:Resultats!$O4)) -> 1.212682 | W4: =IF(Resultats!F4="","",Resultats!F4/AVERAGE(Resultats!$C4:Resultats!$O4)) -> 1.2131793 | X4: =IF(Resultats!G4="","",Resultats!G4/AVERAGE(Resultats!$C4:Resultats!$O4)) -> 1.1482756 | Y4: =IF(Resultats!H4="","",Resultats!H4/AVERAGE(Resultats!$C4:Resultats!$O4)) -> 1.1443112 | Z4: =IF(Resultats!I4="","",Resultats!I4/AVERAGE(Resultats!$C4:Resultats!$O4)) -> 1.0194343 | AA4: =IF(Resultats!J4="","",Resultats!J4/AVERAGE(Resultats!$C4:Resultats!$O4)) | ... AF4: =IF(Resultats!O4="","",Resultats!O4/AVERAGE(Resultats!$C4:Resultats!$O4))
A5: Groupe | B5: A | C5: B | D5: C | E5: D | F5: E | G5: F | H5: G | I5: H | J5: I | K5: J | L5: K | M5: L | N5: P | P5: A | Q5: 2642025 | S5: me_at_the_zoo | T5: =IF(Resultats!C5="","",Resultats!C5/AVERAGE(Resultats!$C5:Resultats!$O5)) -> 1.0618833 | U5: =IF(Resultats!D5="","",Resultats!D5/AVERAGE(Resultats!$C5:Resultats!$O5)) -> 0.63086499 | V5: =IF(Resultats!E5="","",Resultats!E5/AVERAGE(Resultats!$C5:Resultats!$O5)) -> 1.0706831 | W5: =IF(Resultats!F5="","",Resultats!F5/AVERAGE(Resultats!$C5:Resultats!$O5)) -> 1.0618833 | X5: =IF(Resultats!G5="","",Resultats!G5/AVERAGE(Resultats!$C5:Resultats!$O5)) -> 1.0571019 | Y5: =IF(Resultats!H5="","",Resultats!H5/AVERAGE(Resultats!$C5:Resultats!$O5)) -> 1.0397093 | Z5: =IF(Resultats!I5="","",Resultats!I5/AVERAGE(Resultats!$C5:Resultats!$O5)) -> 1.0269183 | AA5: =IF(Resultats!J5="","",Resultats!J5/AVERAGE(Resultats!$C5:Resultats!$O5)) | ... AF5: =IF(Resultats!O5="","",Resultats!O5/AVERAGE(Resultats!$C5:Resultats!$O5))
A6: TOTAL | B6: =Resultats!C9 -> 2642025 | C6: =Resultats!D9 -> 1161045 | D6: =Resultats!E9 -> 2644373 | E6: =Resultats!F9 -> 2639372 | F6: =Resultats!G9 -> 2578160 | G6: =Resultats!H9 -> 2565015 | H6: =Resultats!I9 -> 1551752 | I6: =Resultats!J9 -> 0 | ... N6: =Resultats!O9 -> 0 | P6: D | Q6: 2639372 | S6: trending_today | T6: =IF(Resultats!C6="","",Resultats!C6/AVERAGE(Resultats!$C6:Resultats!$O6)) -> 1.0399803 | U6: =IF(Resultats!D6="","",Resultats!D6/AVERAGE(Resultats!$C6:Resultats!$O6)) -> 0.68035975 | V6: =IF(Resultats!E6="","",Resultats!E6/AVERAGE(Resultats!$C6:Resultats!$O6)) -> 1.0399803 | W6: =IF(Resultats!F6="","",Resultats!F6/AVERAGE(Resultats!$C6:Resultats!$O6)) -> 1.0399803 | X6: =IF(Resultats!G6="","",Resultats!G6/AVERAGE(Resultats!$C6:Resultats!$O6)) -> 1.0400073 | Y6: =IF(Resultats!H6="","",Resultats!H6/AVERAGE(Resultats!$C6:Resultats!$O6)) -> 1.0399803 | Z6: =IF(Resultats!I6="","",Resultats!I6/AVERAGE(Resultats!$C6:Resultats!$O6)) -> 1.0400323 | AA6: =IF(Resultats!J6="","",Resultats!J6/AVERAGE(Resultats!$C6:Resultats!$O6)) | ... AF6: =IF(Resultats!O6="","",Resultats!O6/AVERAGE(Resultats!$C6:Resultats!$O6))
A7: Classement | B7: =IF(B6=0, $N$4, RANK(B6,$B$6:$N$6,0)) -> 3 | C7: =IF(C6=0, $N$4, RANK(C6,$B$6:$N$6,0)) -> 9 | D7: =IF(D6=0, $N$4, RANK(D6,$B$6:$N$6,0)) -> 2 | E7: =IF(E6=0, $N$4, RANK(E6,$B$6:$N$6,0)) -> 4 | F7: =IF(F6=0, $N$4, RANK(F6,$B$6:$N$6,0)) -> 5 | G7: =IF(G6=0, $N$4, RANK(G6,$B$6:$N$6,0)) -> 6 | H7: =IF(H6=0, $N$4, RANK(H6,$B$6:$N$6,0)) -> 8 | I7: =IF(I6=0, $N$4, RANK(I6,$B$6:$N$6,0)) -> 13 | ... N7: =IF(N6=0, $N$4, RANK(N6,$B$6:$N$6,0)) -> 13 | P7: E | Q7: 2578160 | S7: videos_worth_spreading | T7: =IF(Resultats!C7="","",Resultats!C7/AVERAGE(Resultats!$C7:Resultats!$O7)) -> 1.1521079 | U7: =IF(Resultats!D7="","",Resultats!D7/AVERAGE(Resultats!$C7:Resultats!$O7)) -> 0.046619533 | V7: =IF(Resultats!E7="","",Resultats!E7/AVERAGE(Resultats!$C7:Resultats!$O7)) -> 1.1502223 | W7: =IF(Resultats!F7="","",Resultats!F7/AVERAGE(Resultats!$C7:Resultats!$O7)) -> 1.147941 | X7: =IF(Resultats!G7="","",Resultats!G7/AVERAGE(Resultats!$C7:Resultats!$O7)) -> 1.1399237 | Y7: =IF(Resultats!H7="","",Resultats!H7/AVERAGE(Resultats!$C7:Resultats!$O7)) -> 1.1371489 | Z7: =IF(Resultats!I7="","",Resultats!I7/AVERAGE(Resultats!$C7:Resultats!$O7)) -> 1.0560018 | AA7: =IF(Resultats!J7="","",Resultats!J7/AVERAGE(Resultats!$C7:Resultats!$O7)) | ... AF7: =IF(Resultats!O7="","",Resultats!O7/AVERAGE(Resultats!$C7:Resultats!$O7))
P8: F | Q8: 2565015 | S8: custom_dejavu42 | T8: =IF(Resultats!C21="","",Resultats!C21/AVERAGE(Resultats!$C21:Resultats!$O21)) -> 1.1654364 | U8: =IF(Resultats!D21="","",Resultats!D21/AVERAGE(Resultats!$C21:Resultats!$O21)) -> 0.12031392 | V8: =IF(Resultats!E21="","",Resultats!E21/AVERAGE(Resultats!$C21:Resultats!$O21)) -> 1.1627523 | W8: =IF(Resultats!F21="","",Resultats!F21/AVERAGE(Resultats!$C21:Resultats!$O21)) -> 1.1605907 | X8: =IF(Resultats!G21="","",Resultats!G21/AVERAGE(Resultats!$C21:Resultats!$O21)) -> 1.1273553 | Y8: =IF(Resultats!H21="","",Resultats!H21/AVERAGE(Resultats!$C21:Resultats!$O21)) -> 1.1218791 | Z8: =IF(Resultats!I21="","",Resultats!I21/AVERAGE(Resultats!$C21:Resultats!$O21)) -> 1.0771149 | AA8: =IF(Resultats!J21="","",Resultats!J21/AVERAGE(Resultats!$C21:Resultats!$O21)) | ... AF8: =IF(Resultats!O21="","",Resultats!O21/AVERAGE(Resultats!$C21:Resultats!$O21))
P9: J | Q9: 1694905 | S9: custom_universallambda42 | T9: =IF(Resultats!C22="","",Resultats!C22/AVERAGE(Resultats!$C22:Resultats!$O22)) -> 1.1163443 | U9: =IF(Resultats!D22="","",Resultats!D22/AVERAGE(Resultats!$C22:Resultats!$O22)) -> 0.19891315 | V9: =IF(Resultats!E22="","",Resultats!E22/AVERAGE(Resultats!$C22:Resultats!$O22)) -> 1.11563 | W9: =IF(Resultats!F22="","",Resultats!F22/AVERAGE(Resultats!$C22:Resultats!$O22)) -> 1.1138059 | X9: =IF(Resultats!G22="","",Resultats!G22/AVERAGE(Resultats!$C22:Resultats!$O22)) -> 1.1162412 | Y9: =IF(Resultats!H22="","",Resultats!H22/AVERAGE(Resultats!$C22:Resultats!$O22)) -> 1.1155727 | Z9: =IF(Resultats!I22="","",Resultats!I22/AVERAGE(Resultats!$C22:Resultats!$O22)) -> 1.1132771 | AA9: =IF(Resultats!J22="","",Resultats!J22/AVERAGE(Resultats!$C22:Resultats!$O22)) | ... AF9: =IF(Resultats!O22="","",Resultats!O22/AVERAGE(Resultats!$C22:Resultats!$O22))
A10: Classement moyenne du ratio au meilleur | P10: G | Q10: 1551752 | S10: custom_universallambda42_asymmetric | T10: =IF(Resultats!C23="","",Resultats!C23/AVERAGE(Resultats!$C23:Resultats!$O23)) -> 1.1837544 | U10: =IF(Resultats!D23="","",Resultats!D23/AVERAGE(Resultats!$C23:Resultats!$O23)) -> 0.55773995 | V10: =IF(Resultats!E23="","",Resultats!E23/AVERAGE(Resultats!$C23:Resultats!$O23)) -> 1.1831513 | W10: =IF(Resultats!F23="","",Resultats!F23/AVERAGE(Resultats!$C23:Resultats!$O23)) -> 1.1829669 | X10: =IF(Resultats!G23="","",Resultats!G23/AVERAGE(Resultats!$C23:Resultats!$O23)) -> 1.1792876 | Y10: =IF(Resultats!H23="","",Resultats!H23/AVERAGE(Resultats!$C23:Resultats!$O23)) -> 1.1792306 | Z10: =IF(Resultats!I23="","",Resultats!I23/AVERAGE(Resultats!$C23:Resultats!$O23)) -> 1.1793289 | AA10: =IF(Resultats!J23="","",Resultats!J23/AVERAGE(Resultats!$C23:Resultats!$O23)) | ... AF10: =IF(Resultats!O23="","",Resultats!O23/AVERAGE(Resultats!$C23:Resultats!$O23))
N11: =COUNTA(B12:N12) -> 13 | P11: B | Q11: 1161045 | S11: instance1 | T11: =IF(Resultats!C24="","",Resultats!C24/AVERAGE(Resultats!$C24:Resultats!$O24)) -> 1.069736 | U11: =IF(Resultats!D24="","",Resultats!D24/AVERAGE(Resultats!$C24:Resultats!$O24)) -> 0.97422764 | V11: =IF(Resultats!E24="","",Resultats!E24/AVERAGE(Resultats!$C24:Resultats!$O24)) -> 1.0685528 | W11: =IF(Resultats!F24="","",Resultats!F24/AVERAGE(Resultats!$C24:Resultats!$O24)) -> 1.0685614 | X11: =IF(Resultats!G24="","",Resultats!G24/AVERAGE(Resultats!$C24:Resultats!$O24)) -> 1.0685614 | Y11: =IF(Resultats!H24="","",Resultats!H24/AVERAGE(Resultats!$C24:Resultats!$O24)) -> 1.012388 | Z11: =IF(Resultats!I24="","",Resultats!I24/AVERAGE(Resultats!$C24:Resultats!$O24)) -> 0.98767635 | AA11: =IF(Resultats!J24="","",Resultats!J24/AVERAGE(Resultats!$C24:Resultats!$O24)) | ... AF11: =IF(Resultats!O24="","",Resultats!O24/AVERAGE(Resultats!$C24:Resultats!$O24))
A12: Groupe | B12: A | C12: B | D12: C | E12: D | F12: E | G12: F | H12: G | I12: H | J12: I | K12: J | L12: K | M12: L | N12: P | P12: H | Q12: 0 | S12: instance2 | T12: =IF(Resultats!C25="","",Resultats!C25/AVERAGE(Resultats!$C25:Resultats!$O25)) -> 1.1386853 | U12: =IF(Resultats!D25="","",Resultats!D25/AVERAGE(Resultats!$C25:Resultats!$O25)) -> 0.35988478 | V12: =IF(Resultats!E25="","",Resultats!E25/AVERAGE(Resultats!$C25:Resultats!$O25)) -> 1.1356085 | W12: =IF(Resultats!F25="","",Resultats!F25/AVERAGE(Resultats!$C25:Resultats!$O25)) -> 1.1358182 | X12: =IF(Resultats!G25="","",Resultats!G25/AVERAGE(Resultats!$C25:Resultats!$O25)) -> 1.1089185 | Y12: =IF(Resultats!H25="","",Resultats!H25/AVERAGE(Resultats!$C25:Resultats!$O25)) -> 1.1066308 | Z12: =IF(Resultats!I25="","",Resultats!I25/AVERAGE(Resultats!$C25:Resultats!$O25)) -> 1.0885441 | AA12: =IF(Resultats!J25="","",Resultats!J25/AVERAGE(Resultats!$C25:Resultats!$O25)) | ... AF12: =IF(Resultats!O25="","",Resultats!O25/AVERAGE(Resultats!$C25:Resultats!$O25))
A13: kittens | B13: =IF(Resultats!C4="","",Resultats!C4/Resultats!$B4) -> 0.99753873 | C13: =IF(Resultats!D4="","",Resultats!D4/Resultats!$B4) -> 0.49505453 | D13: =IF(Resultats!E4="","",Resultats!E4/Resultats!$B4) -> 0.99669977 | E13: =IF(Resultats!F4="","",Resultats!F4/Resultats!$B4) -> 0.99710852 | F13: =IF(Resultats!G4="","",Resultats!G4/Resultats!$B4) -> 0.94376433 | G13: =IF(Resultats!H4="","",Resultats!H4/Resultats!$B4) -> 0.94050605 | H13: =IF(Resultats!I4="","",Resultats!I4/Resultats!$B4) -> 0.83787006 | I13: =IF(Resultats!J4="","",Resultats!J4/Resultats!$B4) | ... N13: =IF(Resultats!O4="","",Resultats!O4/Resultats!$B4) | P13: I | Q13: 0 | S13: =Resultats!A26 -> 4990_246_84901_50.in | T13: =IF(Resultats!C26="","",Resultats!C26/AVERAGE(Resultats!$C26:Resultats!$O26)) -> 1.1229415 | U13: =IF(Resultats!D26="","",Resultats!D26/AVERAGE(Resultats!$C26:Resultats!$O26)) | V13: =IF(Resultats!E26="","",Resultats!E26/AVERAGE(Resultats!$C26:Resultats!$O26)) -> 1.123007 | W13: =IF(Resultats!F26="","",Resultats!F26/AVERAGE(Resultats!$C26:Resultats!$O26)) | X13: =IF(Resultats!G26="","",Resultats!G26/AVERAGE(Resultats!$C26:Resultats!$O26)) -> 1.0822232 | Y13: =IF(Resultats!H26="","",Resultats!H26/AVERAGE(Resultats!$C26:Resultats!$O26)) -> 1.0792044 | Z13: =IF(Resultats!I26="","",Resultats!I26/AVERAGE(Resultats!$C26:Resultats!$O26)) -> 1.068659 | AA13: =IF(Resultats!J26="","",Resultats!J26/AVERAGE(Resultats!$C26:Resultats!$O26)) | ... AF13: =IF(Resultats!O26="","",Resultats!O26/AVERAGE(Resultats!$C26:Resultats!$O26))
A14: me_at_the_zoo | B14: =IF(Resultats!C5="","",Resultats!C5/Resultats!$B5) -> 0.98325257 | C14: =IF(Resultats!D5="","",Resultats!D5/Resultats!$B5) -> 0.58415044 | D14: =IF(Resultats!E5="","",Resultats!E5/Resultats!$B5) -> 0.99140076 | E14: =IF(Resultats!F5="","",Resultats!F5/Resultats!$B5) -> 0.98325257 | F14: =IF(Resultats!G5="","",Resultats!G5/Resultats!$B5) -> 0.97882518 | G14: =IF(Resultats!H5="","",Resultats!H5/Resultats!$B5) -> 0.96272047 | H14: =IF(Resultats!I5="","",Resultats!I5/Resultats!$B5) -> 0.95087667 | I14: =IF(Resultats!J5="","",Resultats!J5/Resultats!$B5) | ... N14: =IF(Resultats!O5="","",Resultats!O5/Resultats!$B5) | P14: L | Q14: 0 | S14: =Resultats!A27 -> 6970_311_100000_69.in | T14: =IF(Resultats!C27="","",Resultats!C27/AVERAGE(Resultats!$C27:Resultats!$O27)) -> 1.068975 | U14: =IF(Resultats!D27="","",Resultats!D27/AVERAGE(Resultats!$C27:Resultats!$O27)) | V14: =IF(Resultats!E27="","",Resultats!E27/AVERAGE(Resultats!$C27:Resultats!$O27)) -> 1.0690675 | W14: =IF(Resultats!F27="","",Resultats!F27/AVERAGE(Resultats!$C27:Resultats!$O27)) | X14: =IF(Resultats!G27="","",Resultats!G27/AVERAGE(Resultats!$C27:Resultats!$O27)) -> 1.0511163 | Y14: =IF(Resultats!H27="","",Resultats!H27/AVERAGE(Resultats!$C27:Resultats!$O27)) -> 1.0489427 | Z14: =IF(Resultats!I27="","",Resultats!I27/AVERAGE(Resultats!$C27:Resultats!$O27)) -> 1.0328124 | AA14: =IF(Resultats!J27="","",Resultats!J27/AVERAGE(Resultats!$C27:Resultats!$O27)) | ... AF14: =IF(Resultats!O27="","",Resultats!O27/AVERAGE(Resultats!$C27:Resultats!$O27))
A15: trending_today | B15: =IF(Resultats!C6="","",Resultats!C6/Resultats!$B6) -> 0.999932 | C15: =IF(Resultats!D6="","",Resultats!D6/Resultats!$B6) -> 0.65416 | D15: =IF(Resultats!E6="","",Resultats!E6/Resultats!$B6) -> 0.999932 | E15: =IF(Resultats!F6="","",Resultats!F6/Resultats!$B6) -> 0.999932 | F15: =IF(Resultats!G6="","",Resultats!G6/Resultats!$B6) -> 0.999958 | G15: =IF(Resultats!H6="","",Resultats!H6/Resultats!$B6) -> 0.999932 | H15: =IF(Resultats!I6="","",Resultats!I6/Resultats!$B6) -> 0.999982 | I15: =IF(Resultats!J6="","",Resultats!J6/Resultats!$B6) | ... N15: =IF(Resultats!O6="","",Resultats!O6/Resultats!$B6) | P15: P | Q15: 0 | S15: =Resultats!A28 -> 10000_500_100000_100.in | T15: =IF(Resultats!C28="","",Resultats!C28/AVERAGE(Resultats!$C28:Resultats!$O28)) -> 1.081617 | U15: =IF(Resultats!D28="","",Resultats!D28/AVERAGE(Resultats!$C28:Resultats!$O28)) | V15: =IF(Resultats!E28="","",Resultats!E28/AVERAGE(Resultats!$C28:Resultats!$O28)) -> 1.0816374 | W15: =IF(Resultats!F28="","",Resultats!F28/AVERAGE(Resultats!$C28:Resultats!$O28)) | X15: =IF(Resultats!G28="","",Resultats!G28/AVERAGE(Resultats!$C28:Resultats!$O28)) -> 1.0816416 | Y15: =IF(Resultats!H28="","",Resultats!H28/AVERAGE(Resultats!$C28:Resultats!$O28)) -> 1.0803572 | Z15: =IF(Resultats!I28="","",Resultats!I28/AVERAGE(Resultats!$C28:Resultats!$O28)) -> 1.0747022 | AA15: =IF(Resultats!J28="","",Resultats!J28/AVERAGE(Resultats!$C28:Resultats!$O28)) | ... AF15: =IF(Resultats!O28="","",Resultats!O28/AVERAGE(Resultats!$C28:Resultats!$O28))
A16: videos_worth_spreading | B16: =IF(Resultats!C7="","",Resultats!C7/Resultats!$B7) -> 0.99520296 | C16: =IF(Resultats!D7="","",Resultats!D7/Resultats!$B7) -> 0.040270444 | D16: =IF(Resultats!E7="","",Resultats!E7/Resultats!$B7) -> 0.99357411 | E16: =IF(Resultats!F7="","",Resultats!F7/Resultats!$B7) -> 0.99160354 | F16: =IF(Resultats!G7="","",Resultats!G7/Resultats!$B7) -> 0.9846781 | G16: =IF(Resultats!H7="","",Resultats!H7/Resultats!$B7) -> 0.9822812 | H16: =IF(Resultats!I7="","",Resultats!I7/Resultats!$B7) -> 0.91218544 | I16: =IF(Resultats!J7="","",Resultats!J7/Resultats!$B7) | ... N16: =IF(Resultats!O7="","",Resultats!O7/Resultats!$B7) | S16: =Resultats!A29 -> 3860_246_84901_66.in | T16: =IF(Resultats!C29="","",Resultats!C29/AVERAGE(Resultats!$C29:Resultats!$O29)) -> 1.0677595 | U16: =IF(Resultats!D29="","",Resultats!D29/AVERAGE(Resultats!$C29:Resultats!$O29)) | V16: =IF(Resultats!E29="","",Resultats!E29/AVERAGE(Resultats!$C29:Resultats!$O29)) -> 1.0677946 | W16: =IF(Resultats!F29="","",Resultats!F29/AVERAGE(Resultats!$C29:Resultats!$O29)) | X16: =IF(Resultats!G29="","",Resultats!G29/AVERAGE(Resultats!$C29:Resultats!$O29)) -> 1.0684143 | Y16: =IF(Resultats!H29="","",Resultats!H29/AVERAGE(Resultats!$C29:Resultats!$O29)) -> 1.0675062 | Z16: =IF(Resultats!I29="","",Resultats!I29/AVERAGE(Resultats!$C29:Resultats!$O29)) -> 1.0637786 | AA16: =IF(Resultats!J29="","",Resultats!J29/AVERAGE(Resultats!$C29:Resultats!$O29)) | ... AF16: =IF(Resultats!O29="","",Resultats!O29/AVERAGE(Resultats!$C29:Resultats!$O29))
A17: custom_dejavu42 | B17: =IF(Resultats!C21="","",Resultats!C21/Resultats!$B21) -> 1 | C17: =IF(Resultats!D21="","",Resultats!D21/Resultats!$B21) -> 0.10323508 | D17: =IF(Resultats!E21="","",Resultats!E21/Resultats!$B21) -> 0.99769696 | E17: =IF(Resultats!F21="","",Resultats!F21/Resultats!$B21) -> 0.99584216 | F17: =IF(Resultats!G21="","",Resultats!G21/Resultats!$B21) -> 0.96732461 | G17: =IF(Resultats!H21="","",Resultats!H21/Resultats!$B21) -> 0.96262578 | H17: =IF(Resultats!I21="","",Resultats!I21/Resultats!$B21) -> 0.92421596 | I17: =IF(Resultats!J21="","",Resultats!J21/Resultats!$B21) | ... N17: =IF(Resultats!O21="","",Resultats!O21/Resultats!$B21) | S17: =Resultats!A30 -> regional_instance.in | T17: =IF(Resultats!C30="","",Resultats!C30/AVERAGE(Resultats!$C30:Resultats!$O30)) -> 1.0088586 | U17: =IF(Resultats!D30="","",Resultats!D30/AVERAGE(Resultats!$C30:Resultats!$O30)) | V17: =IF(Resultats!E30="","",Resultats!E30/AVERAGE(Resultats!$C30:Resultats!$O30)) -> 1.0123858 | W17: =IF(Resultats!F30="","",Resultats!F30/AVERAGE(Resultats!$C30:Resultats!$O30)) | X17: =IF(Resultats!G30="","",Resultats!G30/AVERAGE(Resultats!$C30:Resultats!$O30)) -> 1.0103638 | Y17: =IF(Resultats!H30="","",Resultats!H30/AVERAGE(Resultats!$C30:Resultats!$O30)) -> 1.0018544 | Z17: =IF(Resultats!I30="","",Resultats!I30/AVERAGE(Resultats!$C30:Resultats!$O30)) -> 0.9851585 | AA17: =IF(Resultats!J30="","",Resultats!J30/AVERAGE(Resultats!$C30:Resultats!$O30)) | ... AF17: =IF(Resultats!O30="","",Resultats!O30/AVERAGE(Resultats!$C30:Resultats!$O30))
A18: custom_universallambda42 | B18: =IF(Resultats!C22="","",Resultats!C22/Resultats!$B22) -> 1 | C18: =IF(Resultats!D22="","",Resultats!D22/Resultats!$B22) -> 0.17818263 | D18: =IF(Resultats!E22="","",Resultats!E22/Resultats!$B22) -> 0.99936023 | E18: =IF(Resultats!F22="","",Resultats!F22/Resultats!$B22) -> 0.99772618 | F18: =IF(Resultats!G22="","",Resultats!G22/Resultats!$B22) -> 0.99990765 | G18: =IF(Resultats!H22="","",Resultats!H22/Resultats!$B22) -> 0.99930884 | H18: =IF(Resultats!I22="","",Resultats!I22/Resultats!$B22) -> 0.9972525 | I18: =IF(Resultats!J22="","",Resultats!J22/Resultats!$B22) | ... N18: =IF(Resultats!O22="","",Resultats!O22/Resultats!$B22) | S18: =Resultats!A31 -> zipF_instance.in | T18: =IF(Resultats!C31="","",Resultats!C31/AVERAGE(Resultats!$C31:Resultats!$O31)) -> 1.0032527 | U18: =IF(Resultats!D31="","",Resultats!D31/AVERAGE(Resultats!$C31:Resultats!$O31)) | V18: =IF(Resultats!E31="","",Resultats!E31/AVERAGE(Resultats!$C31:Resultats!$O31)) -> 1.0115748 | W18: =IF(Resultats!F31="","",Resultats!F31/AVERAGE(Resultats!$C31:Resultats!$O31)) | X18: =IF(Resultats!G31="","",Resultats!G31/AVERAGE(Resultats!$C31:Resultats!$O31)) -> 1.0046736 | Y18: =IF(Resultats!H31="","",Resultats!H31/AVERAGE(Resultats!$C31:Resultats!$O31)) -> 0.99567164 | Z18: =IF(Resultats!I31="","",Resultats!I31/AVERAGE(Resultats!$C31:Resultats!$O31)) -> 0.99036778 | AA18: =IF(Resultats!J31="","",Resultats!J31/AVERAGE(Resultats!$C31:Resultats!$O31)) | ... AF18: =IF(Resultats!O31="","",Resultats!O31/AVERAGE(Resultats!$C31:Resultats!$O31))
A19: custom_universallambda42_asymmetric | B19: =IF(Resultats!C23="","",Resultats!C23/Resultats!$B23) -> 1 | C19: =IF(Resultats!D23="","",Resultats!D23/Resultats!$B23) -> 0.47116187 | D19: =IF(Resultats!E23="","",Resultats!E23/Resultats!$B23) -> 0.99949053 | E19: =IF(Resultats!F23="","",Resultats!F23/Resultats!$B23) -> 0.99933471 | F19: =IF(Resultats!G23="","",Resultats!G23/Resultats!$B23) -> 0.9962266 | G19: =IF(Resultats!H23="","",Resultats!H23/Resultats!$B23) -> 0.99617842 | H19: =IF(Resultats!I23="","",Resultats!I23/Resultats!$B23) -> 0.99626146 | I19: =IF(Resultats!J23="","",Resultats!J23/Resultats!$B23) | ... N19: =IF(Resultats!O23="","",Resultats!O23/Resultats!$B23) | S19: =Resultats!A32 -> big.in | T19: =IF(Resultats!C32="","",Resultats!C32/AVERAGE(Resultats!$C32:Resultats!$O32)) -> 0.97214392 | U19: =IF(Resultats!D32="","",Resultats!D32/AVERAGE(Resultats!$C32:Resultats!$O32)) | V19: =IF(Resultats!E32="","",Resultats!E32/AVERAGE(Resultats!$C32:Resultats!$O32)) -> 1.0557122 | W19: =IF(Resultats!F32="","",Resultats!F32/AVERAGE(Resultats!$C32:Resultats!$O32)) | X19: =IF(Resultats!G32="","",Resultats!G32/AVERAGE(Resultats!$C32:Resultats!$O32)) -> 0.97214392 | Y19: =IF(Resultats!H32="","",Resultats!H32/AVERAGE(Resultats!$C32:Resultats!$O32)) -> 0.97214392 | Z19: =IF(Resultats!I32="","",Resultats!I32/AVERAGE(Resultats!$C32:Resultats!$O32)) -> 1.0557122 | AA19: =IF(Resultats!J32="","",Resultats!J32/AVERAGE(Resultats!$C32:Resultats!$O32)) | ... AF19: =IF(Resultats!O32="","",Resultats!O32/AVERAGE(Resultats!$C32:Resultats!$O32))
A20: instance1 | B20: =IF(Resultats!C24="","",Resultats!C24/Resultats!$B24) -> 1 | C20: =IF(Resultats!D24="","",Resultats!D24/Resultats!$B24) -> 0.91071783 | D20: =IF(Resultats!E24="","",Resultats!E24/Resultats!$B24) -> 0.99889393 | E20: =IF(Resultats!F24="","",Resultats!F24/Resultats!$B24) -> 0.99890194 | F20: =IF(Resultats!G24="","",Resultats!G24/Resultats!$B24) -> 0.99890194 | G20: =IF(Resultats!H24="","",Resultats!H24/Resultats!$B24) -> 0.94639051 | H20: =IF(Resultats!I24="","",Resultats!I24/Resultats!$B24) -> 0.92328981 | I20: =IF(Resultats!J24="","",Resultats!J24/Resultats!$B24) | ... N20: =IF(Resultats!O24="","",Resultats!O24/Resultats!$B24) | S20: =Resultats!A33 -> supra.in | T20: =IF(Resultats!C33="","",Resultats!C33/AVERAGE(Resultats!$C33:Resultats!$O33)) -> 0.96341284 | U20: =IF(Resultats!D33="","",Resultats!D33/AVERAGE(Resultats!$C33:Resultats!$O33)) | V20: =IF(Resultats!E33="","",Resultats!E33/AVERAGE(Resultats!$C33:Resultats!$O33)) -> 1.0731743 | W20: =IF(Resultats!F33="","",Resultats!F33/AVERAGE(Resultats!$C33:Resultats!$O33)) | X20: =IF(Resultats!G33="","",Resultats!G33/AVERAGE(Resultats!$C33:Resultats!$O33)) -> 0.96341284 | Y20: =IF(Resultats!H33="","",Resultats!H33/AVERAGE(Resultats!$C33:Resultats!$O33)) -> 0.96341284 | Z20: =IF(Resultats!I33="","",Resultats!I33/AVERAGE(Resultats!$C33:Resultats!$O33)) -> 1.0731743 | AA20: =IF(Resultats!J33="","",Resultats!J33/AVERAGE(Resultats!$C33:Resultats!$O33)) | ... AF20: =IF(Resultats!O33="","",Resultats!O33/AVERAGE(Resultats!$C33:Resultats!$O33))
A21: instance2 | B21: =IF(Resultats!C25="","",Resultats!C25/Resultats!$B25) -> 1 | C21: =IF(Resultats!D25="","",Resultats!D25/Resultats!$B25) -> 0.31605289 | D21: =IF(Resultats!E25="","",Resultats!E25/Resultats!$B25) -> 0.99729789 | E21: =IF(Resultats!F25="","",Resultats!F25/Resultats!$B25) -> 0.99748206 | F21: =IF(Resultats!G25="","",Resultats!G25/Resultats!$B25) -> 0.97385864 | G21: =IF(Resultats!H25="","",Resultats!H25/Resultats!$B25) -> 0.97184956 | H21: =IF(Resultats!I25="","",Resultats!I25/Resultats!$B25) -> 0.95596567 | I21: =IF(Resultats!J25="","",Resultats!J25/Resultats!$B25) | ... N21: =IF(Resultats!O25="","",Resultats!O25/Resultats!$B25) | S21: =Resultats!A34 -> INSATANC2D.in | T21: =IF(Resultats!C34="","",Resultats!C34/AVERAGE(Resultats!$C34:Resultats!$O34)) -> 0.86482766 | U21: =IF(Resultats!D34="","",Resultats!D34/AVERAGE(Resultats!$C34:Resultats!$O34)) | V21: =IF(Resultats!E34="","",Resultats!E34/AVERAGE(Resultats!$C34:Resultats!$O34)) -> 0.86637236 | W21: =IF(Resultats!F34="","",Resultats!F34/AVERAGE(Resultats!$C34:Resultats!$O34)) | X21: =IF(Resultats!G34="","",Resultats!G34/AVERAGE(Resultats!$C34:Resultats!$O34)) -> 1.6419427 | Y21: =IF(Resultats!H34="","",Resultats!H34/AVERAGE(Resultats!$C34:Resultats!$O34)) -> 0.82883289 | Z21: =IF(Resultats!I34="","",Resultats!I34/AVERAGE(Resultats!$C34:Resultats!$O34)) -> 0.79802436 | AA21: =IF(Resultats!J34="","",Resultats!J34/AVERAGE(Resultats!$C34:Resultats!$O34)) | ... AF21: =IF(Resultats!O34="","",Resultats!O34/AVERAGE(Resultats!$C34:Resultats!$O34))
A22: =Resultats!A26 -> 4990_246_84901_50.in | B22: =IF(Resultats!C26="","",Resultats!C26/Resultats!$B26) -> 0.99994163 | C22: =IF(Resultats!D26="","",Resultats!D26/Resultats!$B26) | D22: =IF(Resultats!E26="","",Resultats!E26/Resultats!$B26) -> 1 | E22: =IF(Resultats!F26="","",Resultats!F26/Resultats!$B26) | F22: =IF(Resultats!G26="","",Resultats!G26/Resultats!$B26) -> 0.96368341 | G22: =IF(Resultats!H26="","",Resultats!H26/Resultats!$B26) -> 0.96099523 | H22: =IF(Resultats!I26="","",Resultats!I26/Resultats!$B26) -> 0.95160493 | I22: =IF(Resultats!J26="","",Resultats!J26/Resultats!$B26) | ... N22: =IF(Resultats!O26="","",Resultats!O26/Resultats!$B26) | S22: =Resultats!A35 -> INSTANCED.in | T22: =IF(Resultats!C35="","",Resultats!C35/AVERAGE(Resultats!$C35:Resultats!$O35)) -> 0.99576741 | U22: =IF(Resultats!D35="","",Resultats!D35/AVERAGE(Resultats!$C35:Resultats!$O35)) | V22: =IF(Resultats!E35="","",Resultats!E35/AVERAGE(Resultats!$C35:Resultats!$O35)) -> 1.003013 | W22: =IF(Resultats!F35="","",Resultats!F35/AVERAGE(Resultats!$C35:Resultats!$O35)) | X22: =IF(Resultats!G35="","",Resultats!G35/AVERAGE(Resultats!$C35:Resultats!$O35)) -> 1.001237 | Y22: =IF(Resultats!H35="","",Resultats!H35/AVERAGE(Resultats!$C35:Resultats!$O35)) -> 0.99559678 | Z22: =IF(Resultats!I35="","",Resultats!I35/AVERAGE(Resultats!$C35:Resultats!$O35)) -> 1.0043858 | AA22: =IF(Resultats!J35="","",Resultats!J35/AVERAGE(Resultats!$C35:Resultats!$O35)) | ... AF22: =IF(Resultats!O35="","",Resultats!O35/AVERAGE(Resultats!$C35:Resultats!$O35))
A23: =Resultats!A27 -> 6970_311_100000_69.in | B23: =IF(Resultats!C27="","",Resultats!C27/Resultats!$B27) -> 0.99991342 | C23: =IF(Resultats!D27="","",Resultats!D27/Resultats!$B27) | D23: =IF(Resultats!E27="","",Resultats!E27/Resultats!$B27) -> 1 | E23: =IF(Resultats!F27="","",Resultats!F27/Resultats!$B27) | F23: =IF(Resultats!G27="","",Resultats!G27/Resultats!$B27) -> 0.98320854 | G23: =IF(Resultats!H27="","",Resultats!H27/Resultats!$B27) -> 0.98117529 | H23: =IF(Resultats!I27="","",Resultats!I27/Resultats!$B27) -> 0.96608709 | I23: =IF(Resultats!J27="","",Resultats!J27/Resultats!$B27) | ... N23: =IF(Resultats!O27="","",Resultats!O27/Resultats!$B27) | S23: =Resultats!A36 -> 2_2_2_1.in | T23: =IF(Resultats!C36="","",Resultats!C36/AVERAGE(Resultats!$C36:Resultats!$O36)) -> 0.095439535 | U23: =IF(Resultats!D36="","",Resultats!D36/AVERAGE(Resultats!$C36:Resultats!$O36)) | V23: =IF(Resultats!E36="","",Resultats!E36/AVERAGE(Resultats!$C36:Resultats!$O36)) -> 1.9045605 | W23: =IF(Resultats!F36="","",Resultats!F36/AVERAGE(Resultats!$C36:Resultats!$O36)) | X23: =IF(Resultats!G36="","",Resultats!G36/AVERAGE(Resultats!$C36:Resultats!$O36)) | Y23: =IF(Resultats!H36="","",Resultats!H36/AVERAGE(Resultats!$C36:Resultats!$O36)) -> 0.095439535 | Z23: =IF(Resultats!I36="","",Resultats!I36/AVERAGE(Resultats!$C36:Resultats!$O36)) -> 1.9045605 | AA23: =IF(Resultats!J36="","",Resultats!J36/AVERAGE(Resultats!$C36:Resultats!$O36)) | ... AF23: =IF(Resultats!O36="","",Resultats!O36/AVERAGE(Resultats!$C36:Resultats!$O36))
A24: =Resultats!A28 -> 10000_500_100000_100.in | B24: =IF(Resultats!C28="","",Resultats!C28/Resultats!$B28) -> 0.99997722 | C24: =IF(Resultats!D28="","",Resultats!D28/Resultats!$B28) | D24: =IF(Resultats!E28="","",Resultats!E28/Resultats!$B28) -> 0.99999604 | E24: =IF(Resultats!F28="","",Resultats!F28/Resultats!$B28) | F24: =IF(Resultats!G28="","",Resultats!G28/Resultats!$B28) -> 1 | G24: =IF(Resultats!H28="","",Resultats!H28/Resultats!$B28) -> 0.99881254 | H24: =IF(Resultats!I28="","",Resultats!I28/Resultats!$B28) -> 0.99358436 | I24: =IF(Resultats!J28="","",Resultats!J28/Resultats!$B28) | ... N24: =IF(Resultats!O28="","",Resultats!O28/Resultats!$B28) | S24: =Resultats!A37 -> 4_2_4_2.in | T24: =IF(Resultats!C37="","",Resultats!C37/AVERAGE(Resultats!$C37:Resultats!$O37)) -> 0.68355331 | U24: =IF(Resultats!D37="","",Resultats!D37/AVERAGE(Resultats!$C37:Resultats!$O37)) | V24: =IF(Resultats!E37="","",Resultats!E37/AVERAGE(Resultats!$C37:Resultats!$O37)) -> 1.3005 | W24: =IF(Resultats!F37="","",Resultats!F37/AVERAGE(Resultats!$C37:Resultats!$O37)) | X24: =IF(Resultats!G37="","",Resultats!G37/AVERAGE(Resultats!$C37:Resultats!$O37)) | Y24: =IF(Resultats!H37="","",Resultats!H37/AVERAGE(Resultats!$C37:Resultats!$O37)) -> 0.68355331 | Z24: =IF(Resultats!I37="","",Resultats!I37/AVERAGE(Resultats!$C37:Resultats!$O37)) -> 1.3323933 | AA24: =IF(Resultats!J37="","",Resultats!J37/AVERAGE(Resultats!$C37:Resultats!$O37)) | ... AF24: =IF(Resultats!O37="","",Resultats!O37/AVERAGE(Resultats!$C37:Resultats!$O37))
A25: =Resultats!A29 -> 3860_246_84901_66.in | B25: =IF(Resultats!C29="","",Resultats!C29/Resultats!$B29) -> 0.99938717 | C25: =IF(Resultats!D29="","",Resultats!D29/Resultats!$B29) | D25: =IF(Resultats!E29="","",Resultats!E29/Resultats!$B29) -> 0.99942004 | E25: =IF(Resultats!F29="","",Resultats!F29/Resultats!$B29) | F25: =IF(Resultats!G29="","",Resultats!G29/Resultats!$B29) -> 1 | G25: =IF(Resultats!H29="","",Resultats!H29/Resultats!$B29) -> 0.99915003 | H25: =IF(Resultats!I29="","",Resultats!I29/Resultats!$B29) -> 0.99566115 | I25: =IF(Resultats!J29="","",Resultats!J29/Resultats!$B29) | ... N25: =IF(Resultats!O29="","",Resultats!O29/Resultats!$B29) | S25: =Resultats!A38 -> 6_2_6_2.in | T25: =IF(Resultats!C38="","",Resultats!C38/AVERAGE(Resultats!$C38:Resultats!$O38)) -> 0.85727746 | U25: =IF(Resultats!D38="","",Resultats!D38/AVERAGE(Resultats!$C38:Resultats!$O38)) | V25: =IF(Resultats!E38="","",Resultats!E38/AVERAGE(Resultats!$C38:Resultats!$O38)) -> 0.85727746 | W25: =IF(Resultats!F38="","",Resultats!F38/AVERAGE(Resultats!$C38:Resultats!$O38)) | X25: =IF(Resultats!G38="","",Resultats!G38/AVERAGE(Resultats!$C38:Resultats!$O38)) | Y25: =IF(Resultats!H38="","",Resultats!H38/AVERAGE(Resultats!$C38:Resultats!$O38)) -> 0.85727746 | Z25: =IF(Resultats!I38="","",Resultats!I38/AVERAGE(Resultats!$C38:Resultats!$O38)) -> 1.4281676 | AA25: =IF(Resultats!J38="","",Resultats!J38/AVERAGE(Resultats!$C38:Resultats!$O38)) | ... AF25: =IF(Resultats!O38="","",Resultats!O38/AVERAGE(Resultats!$C38:Resultats!$O38))
A26: =Resultats!A30 -> regional_instance.in | B26: =IF(Resultats!C30="","",Resultats!C30/Resultats!$B30) -> 0.9965159 | C26: =IF(Resultats!D30="","",Resultats!D30/Resultats!$B30) | D26: =IF(Resultats!E30="","",Resultats!E30/Resultats!$B30) -> 1 | E26: =IF(Resultats!F30="","",Resultats!F30/Resultats!$B30) | F26: =IF(Resultats!G30="","",Resultats!G30/Resultats!$B30) -> 0.99800276 | G26: =IF(Resultats!H30="","",Resultats!H30/Resultats!$B30) -> 0.98959748 | H26: =IF(Resultats!I30="","",Resultats!I30/Resultats!$B30) -> 0.9731058 | I26: =IF(Resultats!J30="","",Resultats!J30/Resultats!$B30) | ... N26: =IF(Resultats!O30="","",Resultats!O30/Resultats!$B30) | S26: =Resultats!A39 -> 8_2_8_2.in | T26: =IF(Resultats!C39="","",Resultats!C39/AVERAGE(Resultats!$C39:Resultats!$O39)) -> 0.75599341 | U26: =IF(Resultats!D39="","",Resultats!D39/AVERAGE(Resultats!$C39:Resultats!$O39)) | V26: =IF(Resultats!E39="","",Resultats!E39/AVERAGE(Resultats!$C39:Resultats!$O39)) -> 0.99089252 | W26: =IF(Resultats!F39="","",Resultats!F39/AVERAGE(Resultats!$C39:Resultats!$O39)) | X26: =IF(Resultats!G39="","",Resultats!G39/AVERAGE(Resultats!$C39:Resultats!$O39)) | Y26: =IF(Resultats!H39="","",Resultats!H39/AVERAGE(Resultats!$C39:Resultats!$O39)) -> 0.75599341 | Z26: =IF(Resultats!I39="","",Resultats!I39/AVERAGE(Resultats!$C39:Resultats!$O39)) -> 1.4971207 | AA26: =IF(Resultats!J39="","",Resultats!J39/AVERAGE(Resultats!$C39:Resultats!$O39)) | ... AF26: =IF(Resultats!O39="","",Resultats!O39/AVERAGE(Resultats!$C39:Resultats!$O39))
A27: =Resultats!A31 -> zipF_instance.in | B27: =IF(Resultats!C31="","",Resultats!C31/Resultats!$B31) -> 0.99177316 | C27: =IF(Resultats!D31="","",Resultats!D31/Resultats!$B31) | D27: =IF(Resultats!E31="","",Resultats!E31/Resultats!$B31) -> 1 | E27: =IF(Resultats!F31="","",Resultats!F31/Resultats!$B31) | F27: =IF(Resultats!G31="","",Resultats!G31/Resultats!$B31) -> 0.99317773 | G27: =IF(Resultats!H31="","",Resultats!H31/Resultats!$B31) -> 0.98427882 | H27: =IF(Resultats!I31="","",Resultats!I31/Resultats!$B31) -> 0.97903565 | I27: =IF(Resultats!J31="","",Resultats!J31/Resultats!$B31) | ... N27: =IF(Resultats!O31="","",Resultats!O31/Resultats!$B31) | S27: =Resultats!A40 -> 20_2_20_2.in | T27: =IF(Resultats!C40="","",Resultats!C40/AVERAGE(Resultats!$C40:Resultats!$O40)) -> 0.95024793 | U27: =IF(Resultats!D40="","",Resultats!D40/AVERAGE(Resultats!$C40:Resultats!$O40)) | V27: =IF(Resultats!E40="","",Resultats!E40/AVERAGE(Resultats!$C40:Resultats!$O40)) -> 1.0497521 | W27: =IF(Resultats!F40="","",Resultats!F40/AVERAGE(Resultats!$C40:Resultats!$O40)) | X27: =IF(Resultats!G40="","",Resultats!G40/AVERAGE(Resultats!$C40:Resultats!$O40)) | Y27: =IF(Resultats!H40="","",Resultats!H40/AVERAGE(Resultats!$C40:Resultats!$O40)) -> 0.95024793 | Z27: =IF(Resultats!I40="","",Resultats!I40/AVERAGE(Resultats!$C40:Resultats!$O40)) -> 1.0497521 | AA27: =IF(Resultats!J40="","",Resultats!J40/AVERAGE(Resultats!$C40:Resultats!$O40)) | ... AF27: =IF(Resultats!O40="","",Resultats!O40/AVERAGE(Resultats!$C40:Resultats!$O40))
A28: =Resultats!A32 -> big.in | B28: =IF(Resultats!C32="","",Resultats!C32/Resultats!$B32) -> 0.92084183 | C28: =IF(Resultats!D32="","",Resultats!D32/Resultats!$B32) | D28: =IF(Resultats!E32="","",Resultats!E32/Resultats!$B32) -> 1 | E28: =IF(Resultats!F32="","",Resultats!F32/Resultats!$B32) | F28: =IF(Resultats!G32="","",Resultats!G32/Resultats!$B32) -> 0.92084183 | G28: =IF(Resultats!H32="","",Resultats!H32/Resultats!$B32) -> 0.92084183 | H28: =IF(Resultats!I32="","",Resultats!I32/Resultats!$B32) -> 1 | I28: =IF(Resultats!J32="","",Resultats!J32/Resultats!$B32) | ... N28: =IF(Resultats!O32="","",Resultats!O32/Resultats!$B32) | S28: =Resultats!A41 -> realistic_large_clustered.in | T28: =IF(Resultats!C41="","",Resultats!C41/AVERAGE(Resultats!$C41:Resultats!$O41)) -> 1.0215803 | U28: =IF(Resultats!D41="","",Resultats!D41/AVERAGE(Resultats!$C41:Resultats!$O41)) | V28: =IF(Resultats!E41="","",Resultats!E41/AVERAGE(Resultats!$C41:Resultats!$O41)) -> 1.0242188 | W28: =IF(Resultats!F41="","",Resultats!F41/AVERAGE(Resultats!$C41:Resultats!$O41)) | X28: =IF(Resultats!G41="","",Resultats!G41/AVERAGE(Resultats!$C41:Resultats!$O41)) | Y28: =IF(Resultats!H41="","",Resultats!H41/AVERAGE(Resultats!$C41:Resultats!$O41)) -> 1.0188635 | Z28: =IF(Resultats!I41="","",Resultats!I41/AVERAGE(Resultats!$C41:Resultats!$O41)) -> 0.93533746 | AA28: =IF(Resultats!J41="","",Resultats!J41/AVERAGE(Resultats!$C41:Resultats!$O41)) | ... AF28: =IF(Resultats!O41="","",Resultats!O41/AVERAGE(Resultats!$C41:Resultats!$O41))
A29: =Resultats!A33 -> supra.in | B29: =IF(Resultats!C33="","",Resultats!C33/Resultats!$B33) -> 0.89772261 | C29: =IF(Resultats!D33="","",Resultats!D33/Resultats!$B33) | D29: =IF(Resultats!E33="","",Resultats!E33/Resultats!$B33) -> 1 | E29: =IF(Resultats!F33="","",Resultats!F33/Resultats!$B33) | F29: =IF(Resultats!G33="","",Resultats!G33/Resultats!$B33) -> 0.89772261 | G29: =IF(Resultats!H33="","",Resultats!H33/Resultats!$B33) -> 0.89772261 | H29: =IF(Resultats!I33="","",Resultats!I33/Resultats!$B33) -> 1 | I29: =IF(Resultats!J33="","",Resultats!J33/Resultats!$B33) | ... N29: =IF(Resultats!O33="","",Resultats!O33/Resultats!$B33) | S29: =Resultats!A42 -> realistic_large_random.in | T29: =IF(Resultats!C42="","",Resultats!C42/AVERAGE(Resultats!$C42:Resultats!$O42)) -> 1.0639107 | U29: =IF(Resultats!D42="","",Resultats!D42/AVERAGE(Resultats!$C42:Resultats!$O42)) | V29: =IF(Resultats!E42="","",Resultats!E42/AVERAGE(Resultats!$C42:Resultats!$O42)) -> 1.0642811 | W29: =IF(Resultats!F42="","",Resultats!F42/AVERAGE(Resultats!$C42:Resultats!$O42)) | X29: =IF(Resultats!G42="","",Resultats!G42/AVERAGE(Resultats!$C42:Resultats!$O42)) | Y29: =IF(Resultats!H42="","",Resultats!H42/AVERAGE(Resultats!$C42:Resultats!$O42)) -> 1.0458355 | Z29: =IF(Resultats!I42="","",Resultats!I42/AVERAGE(Resultats!$C42:Resultats!$O42)) -> 0.82597262 | AA29: =IF(Resultats!J42="","",Resultats!J42/AVERAGE(Resultats!$C42:Resultats!$O42)) | ... AF29: =IF(Resultats!O42="","",Resultats!O42/AVERAGE(Resultats!$C42:Resultats!$O42)) | AH29: CLASSEMENT
A30: =Resultats!A34 -> INSATANC2D.in | B30: =IF(Resultats!C34="","",Resultats!C34/Resultats!$B34) -> 0.52671001 | C30: =IF(Resultats!D34="","",Resultats!D34/Resultats!$B34) | D30: =IF(Resultats!E34="","",Resultats!E34/Resultats!$B34) -> 0.52765078 | E30: =IF(Resultats!F34="","",Resultats!F34/Resultats!$B34) | F30: =IF(Resultats!G34="","",Resultats!G34/Resultats!$B34) -> 1 | G30: =IF(Resultats!H34="","",Resultats!H34/Resultats!$B34) -> 0.50478795 | H30: =IF(Resultats!I34="","",Resultats!I34/Resultats!$B34) -> 0.48602448 | I30: =IF(Resultats!J34="","",Resultats!J34/Resultats!$B34) | ... N30: =IF(Resultats!O34="","",Resultats!O34/Resultats!$B34) | S30: =Resultats!A43 -> dense | T30: =IF(Resultats!C43="","",Resultats!C43/AVERAGE(Resultats!$C43:Resultats!$O43)) -> 0.95843499 | U30: =IF(Resultats!D43="","",Resultats!D43/AVERAGE(Resultats!$C43:Resultats!$O43)) | V30: =IF(Resultats!E43="","",Resultats!E43/AVERAGE(Resultats!$C43:Resultats!$O43)) -> 1.0413931 | W30: =IF(Resultats!F43="","",Resultats!F43/AVERAGE(Resultats!$C43:Resultats!$O43)) | X30: =IF(Resultats!G43="","",Resultats!G43/AVERAGE(Resultats!$C43:Resultats!$O43)) | Y30: =IF(Resultats!H43="","",Resultats!H43/AVERAGE(Resultats!$C43:Resultats!$O43)) -> 0.95877872 | Z30: =IF(Resultats!I43="","",Resultats!I43/AVERAGE(Resultats!$C43:Resultats!$O43)) -> 1.0413931 | AA30: =IF(Resultats!J43="","",Resultats!J43/AVERAGE(Resultats!$C43:Resultats!$O43)) | ... AF30: =IF(Resultats!O43="","",Resultats!O43/AVERAGE(Resultats!$C43:Resultats!$O43)) | AH30: Groupe | AI30: Score
A31: =Resultats!A35 -> INSTANCED.in | B31: =IF(Resultats!C35="","",Resultats!C35/Resultats!$B35) -> 0.99141921 | C31: =IF(Resultats!D35="","",Resultats!D35/Resultats!$B35) | D31: =IF(Resultats!E35="","",Resultats!E35/Resultats!$B35) -> 0.99863312 | E31: =IF(Resultats!F35="","",Resultats!F35/Resultats!$B35) | F31: =IF(Resultats!G35="","",Resultats!G35/Resultats!$B35) -> 0.99686491 | G31: =IF(Resultats!H35="","",Resultats!H35/Resultats!$B35) -> 0.99124932 | H31: =IF(Resultats!I35="","",Resultats!I35/Resultats!$B35) -> 1 | I31: =IF(Resultats!J35="","",Resultats!J35/Resultats!$B35) | ... N31: =IF(Resultats!O35="","",Resultats!O35/Resultats!$B35) | S31: =Resultats!A44 -> dense2 | T31: =IF(Resultats!C44="","",Resultats!C44/AVERAGE(Resultats!$C44:Resultats!$O44)) -> 0.20916691 | U31: =IF(Resultats!D44="","",Resultats!D44/AVERAGE(Resultats!$C44:Resultats!$O44)) | V31: =IF(Resultats!E44="","",Resultats!E44/AVERAGE(Resultats!$C44:Resultats!$O44)) -> 1.7909086 | W31: =IF(Resultats!F44="","",Resultats!F44/AVERAGE(Resultats!$C44:Resultats!$O44)) | X31: =IF(Resultats!G44="","",Resultats!G44/AVERAGE(Resultats!$C44:Resultats!$O44)) | Y31: =IF(Resultats!H44="","",Resultats!H44/AVERAGE(Resultats!$C44:Resultats!$O44)) -> 0.20901583 | Z31: =IF(Resultats!I44="","",Resultats!I44/AVERAGE(Resultats!$C44:Resultats!$O44)) -> 1.7909086 | AA31: =IF(Resultats!J44="","",Resultats!J44/AVERAGE(Resultats!$C44:Resultats!$O44)) | ... AF31: =IF(Resultats!O44="","",Resultats!O44/AVERAGE(Resultats!$C44:Resultats!$O44)) | AH31: {=(CHOOSECOLS(SORT(TRANSPOSE(CHOOSEROWS(T41:AF43,1,3,2)),2,TRUE),1,3))} -> K | AI31: 1.1282859
A32: =Resultats!A36 -> 2_2_2_1.in | B32: =IF(Resultats!C36="","",Resultats!C36/Resultats!$B36) -> 0.050111055 | C32: =IF(Resultats!D36="","",Resultats!D36/Resultats!$B36) | D32: =IF(Resultats!E36="","",Resultats!E36/Resultats!$B36) -> 1 | E32: =IF(Resultats!F36="","",Resultats!F36/Resultats!$B36) | F32: =IF(Resultats!G36="","",Resultats!G36/Resultats!$B36) | G32: =IF(Resultats!H36="","",Resultats!H36/Resultats!$B36) -> 0.050111055 | H32: =IF(Resultats!I36="","",Resultats!I36/Resultats!$B36) -> 1 | I32: =IF(Resultats!J36="","",Resultats!J36/Resultats!$B36) | ... N32: =IF(Resultats!O36="","",Resultats!O36/Resultats!$B36) | S32: =Resultats!A45 -> medium_mixed_lambda.in | T32: =IF(Resultats!C45="","",Resultats!C45/AVERAGE(Resultats!$C45:Resultats!$O45)) -> 1.0179192 | U32: =IF(Resultats!D45="","",Resultats!D45/AVERAGE(Resultats!$C45:Resultats!$O45)) | V32: =IF(Resultats!E45="","",Resultats!E45/AVERAGE(Resultats!$C45:Resultats!$O45)) -> 1.0179192 | W32: =IF(Resultats!F45="","",Resultats!F45/AVERAGE(Resultats!$C45:Resultats!$O45)) | X32: =IF(Resultats!G45="","",Resultats!G45/AVERAGE(Resultats!$C45:Resultats!$O45)) | Y32: =IF(Resultats!H45="","",Resultats!H45/AVERAGE(Resultats!$C45:Resultats!$O45)) -> 0.99524044 | Z32: =IF(Resultats!I45="","",Resultats!I45/AVERAGE(Resultats!$C45:Resultats!$O45)) -> 0.96892112 | AA32: =IF(Resultats!J45="","",Resultats!J45/AVERAGE(Resultats!$C45:Resultats!$O45)) | ... AF32: =IF(Resultats!O45="","",Resultats!O45/AVERAGE(Resultats!$C45:Resultats!$O45)) | AH32: D | AI32: 1.1249697
A33: =Resultats!A37 -> 4_2_4_2.in | B33: =IF(Resultats!C37="","",Resultats!C37/Resultats!$B37) -> 0.51302667 | C33: =IF(Resultats!D37="","",Resultats!D37/Resultats!$B37) | D33: =IF(Resultats!E37="","",Resultats!E37/Resultats!$B37) -> 0.97606316 | E33: =IF(Resultats!F37="","",Resultats!F37/Resultats!$B37) | F33: =IF(Resultats!G37="","",Resultats!G37/Resultats!$B37) | G33: =IF(Resultats!H37="","",Resultats!H37/Resultats!$B37) -> 0.51302667 | H33: =IF(Resultats!I37="","",Resultats!I37/Resultats!$B37) -> 1 | I33: =IF(Resultats!J37="","",Resultats!J37/Resultats!$B37) | ... N33: =IF(Resultats!O37="","",Resultats!O37/Resultats!$B37) | S33: =Resultats!A46 -> medium_skew_dense_dejavu.in | T33: =IF(Resultats!C46="","",Resultats!C46/AVERAGE(Resultats!$C46:Resultats!$O46)) -> 1.0242901 | U33: =IF(Resultats!D46="","",Resultats!D46/AVERAGE(Resultats!$C46:Resultats!$O46)) | V33: =IF(Resultats!E46="","",Resultats!E46/AVERAGE(Resultats!$C46:Resultats!$O46)) -> 1.0242901 | W33: =IF(Resultats!F46="","",Resultats!F46/AVERAGE(Resultats!$C46:Resultats!$O46)) | X33: =IF(Resultats!G46="","",Resultats!G46/AVERAGE(Resultats!$C46:Resultats!$O46)) | Y33: =IF(Resultats!H46="","",Resultats!H46/AVERAGE(Resultats!$C46:Resultats!$O46)) -> 0.99268439 | Z33: =IF(Resultats!I46="","",Resultats!I46/AVERAGE(Resultats!$C46:Resultats!$O46)) -> 0.95873549 | AA33: =IF(Resultats!J46="","",Resultats!J46/AVERAGE(Resultats!$C46:Resultats!$O46)) | ... AF33: =IF(Resultats!O46="","",Resultats!O46/AVERAGE(Resultats!$C46:Resultats!$O46)) | AH33: C | AI33: 1.1091327
A34: =Resultats!A38 -> 6_2_6_2.in | B34: =IF(Resultats!C38="","",Resultats!C38/Resultats!$B38) -> 0.60026389 | C34: =IF(Resultats!D38="","",Resultats!D38/Resultats!$B38) | D34: =IF(Resultats!E38="","",Resultats!E38/Resultats!$B38) -> 0.60026389 | E34: =IF(Resultats!F38="","",Resultats!F38/Resultats!$B38) | F34: =IF(Resultats!G38="","",Resultats!G38/Resultats!$B38) | G34: =IF(Resultats!H38="","",Resultats!H38/Resultats!$B38) -> 0.60026389 | H34: =IF(Resultats!I38="","",Resultats!I38/Resultats!$B38) -> 1 | I34: =IF(Resultats!J38="","",Resultats!J38/Resultats!$B38) | ... N34: =IF(Resultats!O38="","",Resultats!O38/Resultats!$B38) | S34: =Resultats!A47 -> medium_skew_sparse_lambda.in | T34: =IF(Resultats!C47="","",Resultats!C47/AVERAGE(Resultats!$C47:Resultats!$O47)) -> 1.0122134 | U34: =IF(Resultats!D47="","",Resultats!D47/AVERAGE(Resultats!$C47:Resultats!$O47)) | V34: =IF(Resultats!E47="","",Resultats!E47/AVERAGE(Resultats!$C47:Resultats!$O47)) -> 1.0122134 | W34: =IF(Resultats!F47="","",Resultats!F47/AVERAGE(Resultats!$C47:Resultats!$O47)) | X34: =IF(Resultats!G47="","",Resultats!G47/AVERAGE(Resultats!$C47:Resultats!$O47)) | Y34: =IF(Resultats!H47="","",Resultats!H47/AVERAGE(Resultats!$C47:Resultats!$O47)) -> 1.0031586 | Z34: =IF(Resultats!I47="","",Resultats!I47/AVERAGE(Resultats!$C47:Resultats!$O47)) -> 0.9724146 | AA34: =IF(Resultats!J47="","",Resultats!J47/AVERAGE(Resultats!$C47:Resultats!$O47)) | ... AF34: =IF(Resultats!O47="","",Resultats!O47/AVERAGE(Resultats!$C47:Resultats!$O47)) | AH34: G | AI34: 1.1031135
A35: =Resultats!A39 -> 8_2_8_2.in | B35: =IF(Resultats!C39="","",Resultats!C39/Resultats!$B39) -> 0.50496491 | C35: =IF(Resultats!D39="","",Resultats!D39/Resultats!$B39) | D35: =IF(Resultats!E39="","",Resultats!E39/Resultats!$B39) -> 0.6618655 | E35: =IF(Resultats!F39="","",Resultats!F39/Resultats!$B39) | F35: =IF(Resultats!G39="","",Resultats!G39/Resultats!$B39) | G35: =IF(Resultats!H39="","",Resultats!H39/Resultats!$B39) -> 0.50496491 | H35: =IF(Resultats!I39="","",Resultats!I39/Resultats!$B39) -> 1 | I35: =IF(Resultats!J39="","",Resultats!J39/Resultats!$B39) | ... N35: =IF(Resultats!O39="","",Resultats!O39/Resultats!$B39) | S35: =Resultats!A48 -> medium_flat_dense_dejavu.in | T35: =IF(Resultats!C48="","",Resultats!C48/AVERAGE(Resultats!$C48:Resultats!$O48)) -> 1.0129821 | U35: =IF(Resultats!D48="","",Resultats!D48/AVERAGE(Resultats!$C48:Resultats!$O48)) | V35: =IF(Resultats!E48="","",Resultats!E48/AVERAGE(Resultats!$C48:Resultats!$O48)) -> 1.0129821 | W35: =IF(Resultats!F48="","",Resultats!F48/AVERAGE(Resultats!$C48:Resultats!$O48)) | X35: =IF(Resultats!G48="","",Resultats!G48/AVERAGE(Resultats!$C48:Resultats!$O48)) | Y35: =IF(Resultats!H48="","",Resultats!H48/AVERAGE(Resultats!$C48:Resultats!$O48)) -> 0.99443869 | Z35: =IF(Resultats!I48="","",Resultats!I48/AVERAGE(Resultats!$C48:Resultats!$O48)) -> 0.97959717 | AA35: =IF(Resultats!J48="","",Resultats!J48/AVERAGE(Resultats!$C48:Resultats!$O48)) | ... AF35: =IF(Resultats!O48="","",Resultats!O48/AVERAGE(Resultats!$C48:Resultats!$O48)) | AH35: E | AI35: 1.0980443
